Traceback (most recent call last):
  File "D:\Programming\Python\tasks\valve\venv\lib\site-packages\urllib3\connectionpool.py", line 677, in urlopen
    chunked=chunked,
  File "D:\Programming\Python\tasks\valve\venv\lib\site-packages\urllib3\connectionpool.py", line 426, in _make_request
    six.raise_from(e, None)
  File "<string>", line 3, in raise_from
  File "D:\Programming\Python\tasks\valve\venv\lib\site-packages\urllib3\connectionpool.py", line 421, in _make_request
    httplib_response = conn.getresponse()
  File "C:\Users\ltearsl\AppData\Local\Programs\Python\Python37\lib\http\client.py", line 1344, in getresponse
    response.begin()
  File "C:\Users\ltearsl\AppData\Local\Programs\Python\Python37\lib\http\client.py", line 306, in begin
    version, status, reason = self._read_status()
  File "C:\Users\ltearsl\AppData\Local\Programs\Python\Python37\lib\http\client.py", line 267, in _read_status
    line = str(self.fp.readline(_MAXLINE + 1), "iso-8859-1")
  File "C:\Users\ltearsl\AppData\Local\Programs\Python\Python37\lib\socket.py", line 589, in readinto
    return self._sock.recv_into(b)
  File "C:\Users\ltearsl\AppData\Local\Programs\Python\Python37\lib\ssl.py", line 1071, in recv_into
    return self.read(nbytes, buffer)
  File "C:\Users\ltearsl\AppData\Local\Programs\Python\Python37\lib\ssl.py", line 929, in read
    return self._sslobj.read(len, buffer)
ConnectionResetError: [WinError 10054] Удаленный хост принудительно разорвал существующее подключение

During handling of the above exception, another exception occurred:

Traceback (most recent call last):
  File "D:\Programming\Python\tasks\valve\venv\lib\site-packages\requests\adapters.py", line 449, in send
    timeout=timeout
  File "D:\Programming\Python\tasks\valve\venv\lib\site-packages\urllib3\connectionpool.py", line 725, in urlopen
    method, url, error=e, _pool=self, _stacktrace=sys.exc_info()[2]
  File "D:\Programming\Python\tasks\valve\venv\lib\site-packages\urllib3\util\retry.py", line 403, in increment
    raise six.reraise(type(error), error, _stacktrace)
  File "D:\Programming\Python\tasks\valve\venv\lib\site-packages\urllib3\packages\six.py", line 734, in reraise
    raise value.with_traceback(tb)
  File "D:\Programming\Python\tasks\valve\venv\lib\site-packages\urllib3\connectionpool.py", line 677, in urlopen
    chunked=chunked,
  File "D:\Programming\Python\tasks\valve\venv\lib\site-packages\urllib3\connectionpool.py", line 426, in _make_request
    six.raise_from(e, None)
  File "<string>", line 3, in raise_from
  File "D:\Programming\Python\tasks\valve\venv\lib\site-packages\urllib3\connectionpool.py", line 421, in _make_request
    httplib_response = conn.getresponse()
  File "C:\Users\ltearsl\AppData\Local\Programs\Python\Python37\lib\http\client.py", line 1344, in getresponse
    response.begin()
  File "C:\Users\ltearsl\AppData\Local\Programs\Python\Python37\lib\http\client.py", line 306, in begin
    version, status, reason = self._read_status()
  File "C:\Users\ltearsl\AppData\Local\Programs\Python\Python37\lib\http\client.py", line 267, in _read_status
    line = str(self.fp.readline(_MAXLINE + 1), "iso-8859-1")
  File "C:\Users\ltearsl\AppData\Local\Programs\Python\Python37\lib\socket.py", line 589, in readinto
    return self._sock.recv_into(b)
  File "C:\Users\ltearsl\AppData\Local\Programs\Python\Python37\lib\ssl.py", line 1071, in recv_into
    return self.read(nbytes, buffer)
  File "C:\Users\ltearsl\AppData\Local\Programs\Python\Python37\lib\ssl.py", line 929, in read
    return self._sslobj.read(len, buffer)
urllib3.exceptions.ProtocolError: ('Connection aborted.', ConnectionResetError(10054, 'Удаленный хост принудительно разорвал существующее подключение', None, 10054, None))

During handling of the above exception, another exception occurred:

Traceback (most recent call last):
  File "D:/Programming/Python/bot/bot.py", line 425, in <module>
    for event in longpoll.listen():
  File "D:\Programming\Python\tasks\valve\venv\lib\site-packages\vk_api\bot_longpoll.py", line 285, in listen
    for event in self.check():
  File "D:\Programming\Python\tasks\valve\venv\lib\site-packages\vk_api\bot_longpoll.py", line 257, in check
    timeout=self.wait + 10
  File "D:\Programming\Python\tasks\valve\venv\lib\site-packages\requests\sessions.py", line 543, in get
    return self.request('GET', url, **kwargs)
  File "D:\Programming\Python\tasks\valve\venv\lib\site-packages\requests\sessions.py", line 530, in request
    resp = self.send(prep, **send_kwargs)
  File "D:\Programming\Python\tasks\valve\venv\lib\site-packages\requests\sessions.py", line 643, in send
    r = adapter.send(request, **kwargs)
  File "D:\Programming\Python\tasks\valve\venv\lib\site-packages\requests\adapters.py", line 498, in send
    raise ConnectionError(err, request=request)
requests.exceptions.ConnectionError: ('Connection aborted.', ConnectionResetError(10054, 'Удаленный хост принудительно разорвал существующее подключение', None, 10054, None))
 2020-06-03 14:50:19.526267

Traceback (most recent call last):
  File "D:/Programming/Python/bot/bot.py", line 882, in <module>
    characters[event.message.from_id] = Warrior(char[0],char[2],char[3],char[4])
  File "D:\Programming\Python\bot\characters.py", line 28, in __init__
    self.str = 5 + str
TypeError: unsupported operand type(s) for +: 'int' and 'str'
 2020-06-03 16:47:43.327760

Traceback (most recent call last):
  File "D:/Programming/Python/bot/bot.py", line 904, in <module>
    mes = create_character(characters[event.message.from_id], event.message.from_id)
  File "D:/Programming/Python/bot/bot.py", line 200, in create_character
    character.agil, character.int, character.inventory))
sqlite3.OperationalError: no such table: characters
 2020-06-03 17:36:28.942673

